Workbook

Sheet Resumo
A1: Resumo da conferência por carrinho
A3: Carrinho | B3: No Word | C3: Confere | D3: Local diferente | E3: Letra final diferente | F3: Não encontrado | G3: No sistema (neste carrinho) | H3: Sistema: não estão no Word
A4: Carrinho 01 ( AZUL) | B4: =COUNTIF(Conferência!$A$4:$A$336,A4) -> 28 | C4: =COUNTIFS(Conferência!$A$4:$A$336,$A4,Conferência!$K$4:$K$336,"Confere") -> 26 | D4: =COUNTIFS(Conferência!$A$4:$A$336,$A4,Conferência!$K$4:$K$336,"Local diferente") -> 0 | E4: =COUNTIFS(Conferência!$A$4:$A$336,$A4,Conferência!$K$4:$K$336,"Letra final diferente") -> 0 | F4: =COUNTIFS(Conferência!$A$4:$A$336,$A4,Conferência!$K$4:$K$336,"Não encontrado") -> 2 | G4: =COUNTIF(Sistema!$F$2:$F$421,A4) -> 29 | H4: =COUNTIFS(Sistema!$F$2:$F$421,A4,Sistema!$H$2:$H$421,"Falta no Word") -> 3
A5: Carrinho 02 ( AMARELO) | B5: =COUNTIF(Conferência!$A$4:$A$336,A5) -> 25 | C5: =COUNTIFS(Conferência!$A$4:$A$336,$A5,Conferência!$K$4:$K$336,"Confere") -> 25 | D5: =COUNTIFS(Conferência!$A$4:$A$336,$A5,Conferência!$K$4:$K$336,"Local diferente") -> 0 | E5: =COUNTIFS(Conferência!$A$4:$A$336,$A5,Conferência!$K$4:$K$336,"Letra final diferente") -> 0 | F5: =COUNTIFS(Conferência!$A$4:$A$336,$A5,Conferência!$K$4:$K$336,"Não encontrado") -> 0 | G5: =COUNTIF(Sistema!$F$2:$F$421,A5) -> 25 | H5: =COUNTIFS(Sistema!$F$2:$F$421,A5,Sistema!$H$2:$H$421,"Falta no Word") -> 0
A6: Carrinho 03 ( VERMELHO - CHROME R11 - ED. IN | B6: =COUNTIF(Conferência!$A$4:$A$336,A6) -> 26 | C6: =COUNTIFS(Conferência!$A$4:$A$336,$A6,Conferência!$K$4:$K$336,"Confere") -> 24 | D6: =COUNTIFS(Conferência!$A$4:$A$336,$A6,Conferência!$K$4:$K$336,"Local diferente") -> 1 | E6: =COUNTIFS(Conferência!$A$4:$A$336,$A6,Conferência!$K$4:$K$336,"Letra final diferente") -> 0 | F6: =COUNTIFS(Conferência!$A$4:$A$336,$A6,Conferência!$K$4:$K$336,"Não encontrado") -> 1 | G6: =COUNTIF(Sistema!$F$2:$F$421,A6) -> 28 | H6: =COUNTIFS(Sistema!$F$2:$F$421,A6,Sistema!$H$2:$H$421,"Falta no Word") -> 4
A7: Carrinho 04 ( LARANJA ) | B7: =COUNTIF(Conferência!$A$4:$A$336,A7) -> 24 | C7: =COUNTIFS(Conferência!$A$4:$A$336,$A7,Conferência!$K$4:$K$336,"Confere") -> 17 | D7: =COUNTIFS(Conferência!$A$4:$A$336,$A7,Conferência!$K$4:$K$336,"Local diferente") -> 2 | E7: =COUNTIFS(Conferência!$A$4:$A$336,$A7,Conferência!$K$4:$K$336,"Letra final diferente") -> 0 | F7: =COUNTIFS(Conferência!$A$4:$A$336,$A7,Conferência!$K$4:$K$336,"Não encontrado") -> 5 | G7: =COUNTIF(Sistema!$F$2:$F$421,A7) -> 23 | H7: =COUNTIFS(Sistema!$F$2:$F$421,A7,Sistema!$H$2:$H$421,"Falta no Word") -> 6
A8: Carrinho 05 ( ROXO) | B8: =COUNTIF(Conferência!$A$4:$A$336,A8) -> 25 | C8: =COUNTIFS(Conferência!$A$4:$A$336,$A8,Conferência!$K$4:$K$336,"Confere") -> 24 | D8: =COUNTIFS(Conferência!$A$4:$A$336,$A8,Conferência!$K$4:$K$336,"Local diferente") -> 1 | E8: =COUNTIFS(Conferência!$A$4:$A$336,$A8,Conferência!$K$4:$K$336,"Letra final diferente") -> 0 | F8: =COUNTIFS(Conferência!$A$4:$A$336,$A8,Conferência!$K$4:$K$336,"Não encontrado") -> 0 | G8: =COUNTIF(Sistema!$F$2:$F$421,A8) -> 25 | H8: =COUNTIFS(Sistema!$F$2:$F$421,A8,Sistema!$H$2:$H$421,"Falta no Word") -> 1
A9: Carrinho 06 ( VERDE) | B9: =COUNTIF(Conferência!$A$4:$A$336,A9) -> 32 | C9: =COUNTIFS(Conferência!$A$4:$A$336,$A9,Conferência!$K$4:$K$336,"Confere") -> 32 | D9: =COUNTIFS(Conferência!$A$4:$A$336,$A9,Conferência!$K$4:$K$336,"Local diferente") -> 0 | E9: =COUNTIFS(Conferência!$A$4:$A$336,$A9,Conferência!$K$4:$K$336,"Letra final diferente") -> 0 | F9: =COUNTIFS(Conferência!$A$4:$A$336,$A9,Conferência!$K$4:$K$336,"Não encontrado") -> 0 | G9: =COUNTIF(Sistema!$F$2:$F$421,A9) -> 32 | H9: =COUNTIFS(Sistema!$F$2:$F$421,A9,Sistema!$H$2:$H$421,"Falta no Word") -> 0
A10: Carrinho 07 - ROSA | B10: =COUNTIF(Conferência!$A$4:$A$336,A10) -> 31 | C10: =COUNTIFS(Conferência!$A$4:$A$336,$A10,Conferência!$K$4:$K$336,"Confere") -> 25 | D10: =COUNTIFS(Conferência!$A$4:$A$336,$A10,Conferência!$K$4:$K$336,"Local diferente") -> 2 | E10: =COUNTIFS(Conferência!$A$4:$A$336,$A10,Conferência!$K$4:$K$336,"Letra final diferente") -> 1 | F10: =COUNTIFS(Conferência!$A$4:$A$336,$A10,Conferência!$K$4:$K$336,"Não encontrado") -> 3 | G10: =COUNTIF(Sistema!$F$2:$F$421,A10) -> 29 | H10: =COUNTIFS(Sistema!$F$2:$F$421,A10,Sistema!$H$2:$H$421,"Falta no Word") -> 3
A11: Carrinho 08 - CINZA | B11: =COUNTIF(Conferência!$A$4:$A$336,A11) -> 28 | C11: =COUNTIFS(Conferência!$A$4:$A$336,$A11,Conferência!$K$4:$K$336,"Confere") -> 25 | D11: =COUNTIFS(Conferência!$A$4:$A$336,$A11,Conferência!$K$4:$K$336,"Local diferente") -> 1 | E11: =COUNTIFS(Conferência!$A$4:$A$336,$A11,Conferência!$K$4:$K$336,"Letra final diferente") -> 0 | F11: =COUNTIFS(Conferência!$A$4:$A$336,$A11,Conferência!$K$4:$K$336,"Não encontrado") -> 2 | G11: =COUNTIF(Sistema!$F$2:$F$421,A11) -> 28 | H11: =COUNTIFS(Sistema!$F$2:$F$421,A11,Sistema!$H$2:$H$421,"Falta no Word") -> 3
A12: Carrinho 10 - MARROM | B12: =COUNTIF(Conferência!$A$4:$A$336,A12) -> 24 | C12: =COUNTIFS(Conferência!$A$4:$A$336,$A12,Conferência!$K$4:$K$336,"Confere") -> 24 | D12: =COUNTIFS(Conferência!$A$4:$A$336,$A12,Conferência!$K$4:$K$336,"Local diferente") -> 0 | E12: =COUNTIFS(Conferência!$A$4:$A$336,$A12,Conferência!$K$4:$K$336,"Letra final diferente") -> 0 | F12: =COUNTIFS(Conferência!$A$4:$A$336,$A12,Conferência!$K$4:$K$336,"Não encontrado") -> 0 | G12: =COUNTIF(Sistema!$F$2:$F$421,A12) -> 26 | H12: =COUNTIFS(Sistema!$F$2:$F$421,A12,Sistema!$H$2:$H$421,"Falta no Word") -> 2
A13: Carrinho 11 - PRETO | B13: =COUNTIF(Conferência!$A$4:$A$336,A13) -> 24 | C13: =COUNTIFS(Conferência!$A$4:$A$336,$A13,Conferência!$K$4:$K$336,"Confere") -> 24 | D13: =COUNTIFS(Conferência!$A$4:$A$336,$A13,Conferência!$K$4:$K$336,"Local diferente") -> 0 | E13: =COUNTIFS(Conferência!$A$4:$A$336,$A13,Conferência!$K$4:$K$336,"Letra final diferente") -> 0 | F13: =COUNTIFS(Conferência!$A$4:$A$336,$A13,Conferência!$K$4:$K$336,"Não encontrado") -> 0 | G13: =COUNTIF(Sistema!$F$2:$F$421,A13) -> 26 | H13: =COUNTIFS(Sistema!$F$2:$F$421,A13,Sistema!$H$2:$H$421,"Falta no Word") -> 2
A14: Carrinho 12 - OCRE | B14: =COUNTIF(Conferência!$A$4:$A$336,A14) -> 25 | C14: =COUNTIFS(Conferência!$A$4:$A$336,$A14,Conferência!$K$4:$K$336,"Confere") -> 23 | D14: =COUNTIFS(Conferência!$A$4:$A$336,$A14,Conferência!$K$4:$K$336,"Local diferente") -> 0 | E14: =COUNTIFS(Conferência!$A$4:$A$336,$A14,Conferência!$K$4:$K$336,"Letra final diferente") -> 0 | F14: =COUNTIFS(Conferência!$A$4:$A$336,$A14,Conferência!$K$4:$K$336,"Não encontrado") -> 2 | G14: =COUNTIF(Sistema!$F$2:$F$421,A14) -> 29 | H14: =COUNTIFS(Sistema!$F$2:$F$421,A14,Sistema!$H$2:$H$421,"Falta no Word") -> 6
A15: CARRINHO RESERVA | B15: =COUNTIF(Conferência!$A$4:$A$336,A15) -> 12 | C15: =COUNTIFS(Conferência!$A$4:$A$336,$A15,Conferência!$K$4:$K$336,"Confere") -> 10 | D15: =COUNTIFS(Conferência!$A$4:$A$336,$A15,Conferência!$K$4:$K$336,"Local diferente") -> 2 | E15: =COUNTIFS(Conferência!$A$4:$A$336,$A15,Conferência!$K$4:$K$336,"Letra final diferente") -> 0 | F15: =COUNTIFS(Conferência!$A$4:$A$336,$A15,Conferência!$K$4:$K$336,"Não encontrado") -> 0 | G15: =COUNTIF(Sistema!$F$2:$F$421,A15) -> 13 | H15: =COUNTIFS(Sistema!$F$2:$F$421,A15,Sistema!$H$2:$H$421,"Falta no Word") -> 3
A16: Carrinho 13 - CIANO | B16: =COUNTIF(Conferência!$A$4:$A$336,A16) -> 29 | C16: =COUNTIFS(Conferência!$A$4:$A$336,$A16,Conferência!$K$4:$K$336,"Confere") -> 12 | D16: =COUNTIFS(Conferência!$A$4:$A$336,$A16,Conferência!$K$4:$K$336,"Local diferente") -> 15 | E16: =COUNTIFS(Conferência!$A$4:$A$336,$A16,Conferência!$K$4:$K$336,"Letra final diferente") -> 1 | F16: =COUNTIFS(Conferência!$A$4:$A$336,$A16,Conferência!$K$4:$K$336,"Não encontrado") -> 1 | G16: =COUNTIF(Sistema!$F$2:$F$421,A16) -> 15 | H16: =COUNTIFS(Sistema!$F$2:$F$421,A16,Sistema!$H$2:$H$421,"Falta no Word") -> 2
A17: Total | B17: =SUM(B4:B16) -> 333 | C17: =SUM(C4:C16) -> 291 | D17: =SUM(D4:D16) -> 24 | E17: =SUM(E4:E16) -> 2 | F17: =SUM(F4:F16) -> 16 | G17: =SUM(G4:G16) -> 328 | H17: =SUM(H4:H16) -> 35
A19: Total de linhas na exportação do sistema | B19: =COUNTA(Sistema!D2:D421) -> 420
A20: Casos a conferir (aba Divergências) | B20: =COUNTA(Divergências!A5:A64) -> 60
A21: Já verificados | B21: =COUNTIF(Divergências!K5:K64,"Sim") -> 0
A23: Alteração combinada: o computador 22 do carrinho verde (09S29QAR109471H, patrimônio 382738), que quebrou a tela, foi tirado do Carrinho 06 e passou a constar no carrinho dos quebrados (13 ciano) como nº 29. As duas trocas já foram feitas no sistema (exportação de 20/10/2026) e conferem. No lugar dele entrou o 09S29QAR110876J (patrimônio 382780), que era o nº 11 da reserva; a reserva ficou com 12 no Word.
A24: O 'Carrinho 13 - CIANO' desta planilha é o Word dos Chromebooks quebrados (o título do Word diz 'ciano'): ele reúne equipamentos de vários carrinhos, por isso muitos aparecem como Local diferente.
A25: Como ler: nos Samsung a comparação usa o N/S sem a letra final (14 primeiros caracteres, ex.: 09S29QBR703384), e a letra final só é comparada quando o sistema também a traz. Nos Acer (N/S de 22 caracteres) compara o N/S inteiro.
A26: O N/S ditado aparece sem espaços e hífens; nada mais foi corrigido. As correções prováveis estão só nas observações.
A27: A exportação do sistema não tem coluna de patrimônio, então o patrimônio do Word não foi conferido.
A28: Os carregadores não foram conferidos.
A29: O Word do carrinho azul se chama 'Carrinho 4 azul' (as etiquetas dos Chromebooks dizem carrinho 4), mas os N/S batem com o Carrinho 01 ( AZUL) do sistema, e nenhum bate com o Carrinho 04. A planilha usa o nome do sistema.
A30: Modelo informado: carrinhos 05, 06, 07, 08 e 10 = Samsung Chromebook 4 cinza; carrinho 03 = Acer Chromebook R11 CB5-132T branco (o nº 26 é um Acer C731 preto); carrinho 13 = Samsung cinza (nº 1 a 16) e Acer preto (nº 17 a 28), com os Chromebooks quebrados; carrinhos 01, 02, 04, 12 e reserva = Acer Chromebook 11 C731 (N16Q13) preto (no 12, o nº 25 é um Samsung cinza; na reserva, do nº 10 ao 13 são Samsung cinza; o cabeçalho do Word da reserva diz 8 Acer + 4 Samsung, mas foram listados 9 Acer + 4 Samsung = 13). No sistema os Samsung variam de lote.
A31: As hipóteses nas observações são palpites: confirme na etiqueta do equipamento. Linhas em amarelo precisam de conferência.

Sheet Divergências
A1: Divergências a conferir (para verificar no final do inventário)
A2: Cada linha é um caso. Quando conferir na etiqueta, marque 'Verificado?' e anote o resultado. Palpites são só hipóteses: vale o que está na etiqueta.
A4: Caso | B4: Carrinho | C4: Nº no Word | D4: Tipo | E4: N/S no Word (ditado) | F4: Patrimônio (Word) | G4: N/S no sistema | H4: Local no sistema | I4: O que provavelmente aconteceu | J4: O que conferir | K4: Verificado? | L4: Resultado da conferência
A5: 1 | B5: Carrinho 01 | C5: 12 | D5: N/S não encontrado no sistema | E5: NXH0HAL001830D20719501 | F5: 413983 | G5: Não existe no sistema | I5: Foi ditado NXH0HAL001830D20719501. Esse N/S não existe no sistema e não é parecido com nenhum dos que sobram no Carrinho 01. Pode ser um erro de ditado maior ou um equipamento que não está cadastrado no sistema (patrimônio 413983). | J5: 1) Olhe a etiqueta do computador 12 do Carrinho 01 e confira o N/S ditado (NXH0HAL001830D20719501). 2) Se a etiqueta tiver outro N/S: foi erro de ditado. Corrija na planilha e procure o número certo no sistema. 3) Se for esse mesmo: o equipamento não está cadastrado no sistema. Avisar quem mantém o sistema. | K5: Não
A6: 2 | B6: Carrinho 01 | C6: 20 | D6: Erro provável de ditado | E6: NXH0HAL001832DD66639501 | F6: 413913 | G6: NXH0HAL001832D66639501 | H6: Carrinho 01 ( AZUL) | I6: Foi ditado NXH0HAL001832DD66639501, com 23 caracteres (um D a mais). No sistema o Carrinho 01 tem NXH0HAL001832D66639501. Deve ser o mesmo equipamento. | J6: 1) Olhe a etiqueta do computador 20 do Carrinho 01. 2) Se o N/S for NXH0HAL001832D66639501: foi só erro de ditado. O sistema está certo; corrija o número na planilha. 3) Se o N/S for outro (como NXH0HAL001832DD66639501): o cadastro do sistema está errado. Avisar quem mantém o sistema. | K6: Não
A7: 3 | B7: Carrinho 01 | C7: — | D7: Sobra no sistema (não está no Word) | E7: — | F7: — | G7: NXH0HAL001832D69D59501 | H7: Carrinho 01 ( AZUL) | I7: Está cadastrado no Carrinho 01, mas nenhum computador do Word do Carrinho 01 tem esse N/S. Ele aparece no Word do Carrinho Reserva (computador 1), então provavelmente está mesmo na reserva e só falta atualizar a localização no sistema. | J7: 1) Procure o equipamento de N/S NXH0HAL001832D69D59501. 2) Se achar em outro carrinho ou na manutenção: atualizar a localização no sistema. 3) Se não achar em lugar nenhum: registrar como não localizado. | K7: Não
A8: 4 | B8: Carrinho 03 | C8: 1 | D8: Erro provável de ditado | E8: NXG54AL00274817F47600 | F8: 408646 | G8: NXG54AL002748177F47600 | H8: Carrinho 03 ( VERMELHO - CHROME R11 - ED. IN | I8: Foi ditado NXG54AL00274817F47600, com um caractere a menos (falta um 7). No sistema o Carrinho 03 tem NXG54AL002748177F47600. Deve ser o mesmo equipamento. | J8: 1) Olhe a etiqueta do computador 1 do Carrinho 03. 2) Se o N/S for NXG54AL002748177F47600: foi só erro de ditado. O sistema está certo; corrija o número na planilha. 3) Se o N/S for outro (como NXG54AL00274817F47600): o cadastro do sistema está errado. Avisar quem mantém o sistema. | K8: Não
A9: 5 | B9: Carrinho 03 | C9: 26 | D9: Local diferente no sistema | E9: NXH0HAL001830D18D69501 | F9: 414451 | G9: NXH0HAL001830D18D69501 | H9: CARRINHO RESERVA | I9: É o Chromebook preto (Acer C731), não um dos brancos do carrinho. O sistema registra este N/S em CARRINHO RESERVA. Pode ser que ele estivesse junto do carrinho na contagem, mas pertence à reserva. | J9: 1) Confirme que o equipamento (N/S NXH0HAL001830D18D69501) está mesmo no Carrinho 03. 2) Se estiver: atualizar a localização no sistema (hoje: CARRINHO RESERVA). 3) Se não estiver: foi erro na contagem. Descubra de qual carrinho ele é e corrija a lista. | K9: Não
A10: 6 | B10: Carrinho 03 | C10: — | D10: Sobra no sistema (não está no Word) | E10: — | F10: — | G10: NXG54AL00274817ADF7600 | H10: Carrinho 03 ( VERMELHO - CHROME R11 - ED. IN | I10: Está cadastrado no Carrinho 03 (Acer branco), mas nenhum computador do Word tem esse N/S. Hipótese, pelo que você contou: está com um professor que trocou o branco pelo cinza. | J10: 1) Procure o equipamento de N/S NXG54AL00274817ADF7600. 2) Se achar em outro carrinho ou na manutenção: atualizar a localização no sistema. 3) Se não achar em lugar nenhum: registrar como não localizado. | K10: Não
A11: 7 | B11: Carrinho 03 | C11: — | D11: Sobra no sistema (não está no Word) | E11: — | F11: — | G11: NXG54AL0027430659B7600 | H11: Carrinho 03 ( VERMELHO - CHROME R11 - ED. IN | I11: Está cadastrado no Carrinho 03 (Acer branco), mas nenhum computador do Word tem esse N/S. Hipótese, pelo que você contou: está com um professor que trocou o branco pelo cinza. | J11: 1) Procure o equipamento de N/S NXG54AL0027430659B7600. 2) Se achar em outro carrinho ou na manutenção: atualizar a localização no sistema. 3) Se não achar em lugar nenhum: registrar como não localizado. | K11: Não
A12: 8 | B12: Carrinho 03 | C12: — | D12: Sobra no sistema (não está no Word) | E12: — | F12: — | G12: 09S29QBR711970 | H12: Carrinho 03 ( VERMELHO - CHROME R11 - ED. IN | I12: Está cadastrado no Carrinho 03, mas é um Samsung Chromebook 4 cinza (não um Acer branco) e não está no Word. Hipótese: é o cinza que um professor recebeu na troca pelo branco. Conferir com quem ele está. Ele aparece no Word dos Chromebooks quebrados (computador 7), então provavelmente está lá e só falta atualizar a localização no sistema. | J12: 1) Procure o equipamento de N/S 09S29QBR711970. 2) Se achar em outro carrinho ou na manutenção: atualizar a localização no sistema. 3) Se não achar em lugar nenhum: registrar como não localizado. | K12: Não
A13: 9 | B13: Carrinho 04 | C13: 4 | D13: Local diferente no sistema | E13: NXH0HAL001830D1FAB9501 | F13: 414345 | G13: NXH0HAL001830D1FAB9501 | H13: Carrinho 01 ( AZUL) | I13: O N/S existe no sistema, mas o cadastro diz que ele está no Carrinho 01 ( AZUL). Como o Word do Carrinho 01 não lista este N/S, ele provavelmente está mesmo no Carrinho 04 e só falta atualizar o cadastro. | J13: 1) Confirme que o equipamento (N/S NXH0HAL001830D1FAB9501) está mesmo no Carrinho 04. 2) Se estiver: atualizar a localização no sistema (hoje: Carrinho 01 ( AZUL)). 3) Se não estiver: foi erro na contagem. Descubra de qual carrinho ele é e corrija a lista. | K13: Não
A14: 10 | B14: Carrinho 04 | C14: 9 | D14: Erro provável de ditado | E14: NXH0HAL001838BE691A9501 | F14: 415279 | G14: NXH0HAL001838E691A9501 | H14: Carrinho 04 ( LARANJA ) | I14: Foi ditado NXH0HAL001838BE691A9501, com 23 caracteres (um B a mais). No sistema o Carrinho 04 tem NXH0HAL001838E691A9501. Deve ser o mesmo equipamento. | J14: 1) Olhe a etiqueta do computador 9 do Carrinho 04. 2) Se o N/S for NXH0HAL001838E691A9501: foi só erro de ditado. O sistema está certo; corrija o número na planilha. 3) Se o N/S for outro (como NXH0HAL001838BE691A9501): o cadastro do sistema está errado. Avisar quem mantém o sistema. | K14: Não
A15: 11 | B15: Carrinho 04 | C15: 12 | D15: Erro provável de ditado | E15: NXH0HAL001832DC459501 | F15: 415334 | G15: NXH0HAL001832D5C459501 | H15: Carrinho 04 ( LARANJA ) | I15: Foi ditado NXH0HAL001832DC459501, com 21 caracteres (falta o 5). No sistema o Carrinho 04 tem NXH0HAL001832D5C459501. Deve ser o mesmo equipamento. | J15: 1) Olhe a etiqueta do computador 12 do Carrinho 04. 2) Se o N/S for NXH0HAL001832D5C459501: foi só erro de ditado. O sistema está certo; corrija o número na planilha. 3) Se o N/S for outro (como NXH0HAL001832DC459501): o cadastro do sistema está errado. Avisar quem mantém o sistema. | K15: Não
A16: 12 | B16: Carrinho 04 | C16: 17 | D16: Erro provável de ditado | E16: NXH0HAL00183BE76A19501 | F16: 415312 | G16: NXH0HAL001838E76A19501 | H16: Carrinho 04 ( LARANJA ) | I16: Foi ditado NXH0HAL00183BE76A19501, com B no lugar de 8. No sistema o Carrinho 04 tem NXH0HAL001838E76A19501. Deve ser o mesmo equipamento. | J16: 1) Olhe a etiqueta do computador 17 do Carrinho 04. 2) Se o N/S for NXH0HAL001838E76A19501: foi só erro de ditado. O sistema está certo; corrija o número na planilha. 3) Se o N/S for outro (como NXH0HAL00183BE76A19501): o cadastro do sistema está errado. Avisar quem mantém o sistema. | K16: Não
A17: 13 | B17: Carrinho 04 | C17: 20 | D17: Erro provável de ditado | E17: NXH0HAL00183BE693B9501 | F17: 415264 | G17: NXH0HAL001838E69389501 | H17: Carrinho 04 ( LARANJA ) | I17: Foi ditado NXH0HAL00183BE693B9501, com dois B no lugar de 8. No sistema o Carrinho 04 tem NXH0HAL001838E69389501. Deve ser o mesmo equipamento. | J17: 1) Olhe a etiqueta do computador 20 do Carrinho 04. 2) Se o N/S for NXH0HAL001838E69389501: foi só erro de ditado. O sistema está certo; corrija o número na planilha. 3) Se o N/S for outro (como NXH0HAL00183BE693B9501): o cadastro do sistema está errado. Avisar quem mantém o sistema. | K17: Não
A18: 14 | B18: Carrinho 04 | C18: 21 | D18: Local diferente no sistema | E18: NXH0HAL001838E68629501 | F18: 415371 | G18: NXH0HAL001838E68629501 | H18: Carrinho 09 - BORDÔ | I18: O N/S existe no sistema, mas o cadastro diz que ele está no Carrinho 09 - BORDÔ. Pode ter mudado de carrinho sem atualizar o sistema, ou ter sido trocado por outro equipamento do Carrinho 04. | J18: 1) Confirme que o equipamento (N/S NXH0HAL001838E68629501) está mesmo no Carrinho 04. 2) Se estiver: atualizar a localização no sistema (hoje: Carrinho 09 - BORDÔ). 3) Se não estiver: foi erro na contagem. Descubra de qual carrinho ele é e corrija a lista. | K18: Não
A19: 15 | B19: Carrinho 04 | C19: 23 | D19: Erro provável de ditado | E19: NXH0HAL001838E74D9501 | F19: 415307 | G19: NXH0HAL001838E748D9501 | H19: Carrinho 04 ( LARANJA ) | I19: Foi ditado NXH0HAL001838E74D9501, com 21 caracteres (falta o 8). No sistema o Carrinho 04 tem NXH0HAL001838E748D9501. Deve ser o mesmo equipamento. | J19: 1) Olhe a etiqueta do computador 23 do Carrinho 04. 2) Se o N/S for NXH0HAL001838E748D9501: foi só erro de ditado. O sistema está certo; corrija o número na planilha. 3) Se o N/S for outro (como NXH0HAL001838E74D9501): o cadastro do sistema está errado. Avisar quem mantém o sistema. | K19: Não
A20: 16 | B20: Carrinho 04 | C20: — | D20: Sobra no sistema (não está no Word) | E20: — | F20: — | G20: NXH0HAL001838E69669501 | H20: Carrinho 04 ( LARANJA ) | I20: Está cadastrado no Carrinho 04, mas nenhum computador do Word tem esse N/S. Ele também não está no Word do Carrinho 01. Hipótese: foi trocado de carrinho com o computador 21 do Word, cadastrado no Carrinho 09. Confira quando chegar ao Carrinho 09. Ele aparece no Word dos Chromebooks quebrados (computador 17), então provavelmente está lá e só falta atualizar a localização no sistema. | J20: 1) Procure o equipamento de N/S NXH0HAL001838E69669501. 2) Se achar em outro carrinho ou na manutenção: atualizar a localização no sistema. 3) Se não achar em lugar nenhum: registrar como não localizado. | K20: Não
A21: 17 | B21: Carrinho 05 | C21: 2 | D21: Local diferente no sistema | E21: 09S29QANC07347V | F21: 382911 | G21: 09S29QANC07347V | H21: Carrinho 12 - OCRE | I21: O N/S existe no sistema, mas o cadastro diz que ele está no Carrinho 12 - OCRE. Como o Word do Carrinho 12 também não lista este N/S, ele provavelmente está mesmo no Carrinho 05 e só falta atualizar o cadastro. | J21: 1) Confirme que o equipamento (N/S 09S29QANC07347) está mesmo no Carrinho 05. 2) Se estiver: atualizar a localização no sistema (hoje: Carrinho 12 - OCRE ). 3) Se não estiver: foi erro na contagem. Descubra de qual carrinho ele é e corrija a lista. | K21: Não
A22: 18 | B22: Carrinho 05 | C22: — | D22: Sobra no sistema (não está no Word) | E22: — | F22: — | G22: 09S29QAR109513J | H22: Carrinho 05 ( ROXO) | I22: Está cadastrado no Carrinho 05, mas nenhum computador do Word tem esse N/S. Ele também não está no Word do Carrinho 12. Hipótese: está com um professor que trocou o Chromebook branco pelo cinza, ou em um carrinho que ainda não foi conferido. Ele aparece no Word dos Chromebooks quebrados (computador 14), então provavelmente está lá e só falta atualizar a localização no sistema. | J22: 1) Procure o equipamento de N/S 09S29QAR109513J. 2) Se achar em outro carrinho ou na manutenção: atualizar a localização no sistema. 3) Se não achar em lugar nenhum: registrar como não localizado. | K22: Não
A23: 19 | B23: Carrinho 07 | C23: 1 | D23: Local diferente no sistema | E23: 09S29QBR712609M | F23: 503621 | G23: 09S29QBR712609 | H23: Não Alocado | I23: O N/S existe no sistema, mas o cadastro diz que ele está em outro lugar (Não Alocado). Provavelmente o equipamento foi colocado no carrinho e a localização não foi atualizada. | J23: 1) Confirme que o equipamento (N/S 09S29QBR712609) está mesmo no Carrinho 07. 2) Se estiver: atualizar a localização no sistema (hoje: Não Alocado). 3) Se não estiver: foi erro na contagem. Descubra de qual carrinho ele é e corrija a lista. | K23: Não
A24: 20 | B24: Carrinho 07 | C24: 10 | D24: Erro provável de ditado | E24: 09S29QBR096225X | F24: 508254 | G24: 09S29QBR906225 | H24: Carrinho 07 - ROSA | I24: Foi ditado 096225, mas no sistema o Carrinho 07 tem 906225 (o 0 e o 9 trocaram de lugar). Deve ser o mesmo equipamento. | J24: 1) Olhe a etiqueta do computador 10 do Carrinho 07. 2) Se o N/S for 09S29QBR906225: foi só erro de ditado. O sistema está certo; corrija o número na planilha. 3) Se o N/S for outro (como 09S29QBR096225X): o cadastro do sistema está errado. Avisar quem mantém o sistema. | K24: Não
A25: 21 | B25: Carrinho 07 | C25: 14 | D25: Local diferente no sistema | E25: 09S29QBR702099V | F25: 505200 | G25: 09S29QBR702099 | H25: Carrinho 13 - CIANO | I25: O N/S existe no sistema, mas o cadastro diz que ele está no Carrinho 13 - CIANO. Ou o equipamento mudou de carrinho e o sistema não foi atualizado, ou a contagem pegou um equipamento de outro carrinho. | J25: 1) Confirme que o equipamento (N/S 09S29QBR702099) está mesmo no Carrinho 07. 2) Se estiver: atualizar a localização no sistema (hoje: Carrinho 13 - CIANO). 3) Se não estiver: foi erro na contagem. Descubra de qual carrinho ele é e corrija a lista. | K25: Não
A26: 22 | B26: Carrinho 07 | C26: 17 | D26: Erro provável de ditado | E26: 09S29QB906223V | F26: 508233 | G26: 09S29QBR906223 | H26: Carrinho 07 - ROSA | I26: Foi ditado 'qb 9 06223', sem o R. No sistema o Carrinho 07 tem QBR906223. Deve ser o mesmo equipamento. | J26: 1) Olhe a etiqueta do computador 17 do Carrinho 07. 2) Se o N/S for 09S29QBR906223: foi só erro de ditado. O sistema está certo; corrija o número na planilha. 3) Se o N/S for outro (como 09S29QB906223V): o cadastro do sistema está errado. Avisar quem mantém o sistema. | K26: Não
A27: 23 | B27: Carrinho 07 | C27: 23 | D27: Letra final diferente | E27: 09S29QANC07195B | F27: 382906 | G27: 09S29QANC07195D | H27: Carrinho 07 - ROSA | I27: O número bate com o sistema, mas a letra final do ditado (B) é diferente da do sistema (D). | J27: 1) Olhe a última letra da etiqueta do computador 23 do Carrinho 07. 2) Se for a do sistema: foi erro de ditado, corrija a letra na planilha. 3) Se for a do ditado: o cadastro do sistema está errado. Avisar quem mantém o sistema. | K27: Não
A28: 24 | B28: Carrinho 07 | C28: 31 | D28: Erro provável de ditado | E28: 09S29QUEBR811879T | F28: 503655 | G28: 09S29QBR811879 | H28: Carrinho 07 - ROSA | I28: Foi ditado 'que BR 811879' (o ditado entendeu QUEBR). No sistema o Carrinho 07 tem QBR811879. Deve ser o mesmo equipamento. | J28: 1) Olhe a etiqueta do computador 31 do Carrinho 07. 2) Se o N/S for 09S29QBR811879: foi só erro de ditado. O sistema está certo; corrija o número na planilha. 3) Se o N/S for outro (como 09S29QUEBR811879T): o cadastro do sistema está errado. Avisar quem mantém o sistema. | K28: Não
A29: 25 | B29: Carrinho 08 | C29: 1 | D29: Erro provável de ditado | E29: 09S29QBR700216N | F29: 505069 | G29: 09S29QAR700216 | H29: Carrinho 08 - CINZA | I29: Foi ditado QBR700216, mas no sistema o Carrinho 08 tem QAR700216 (QAR no lugar de QBR). Pode ser erro de ditado ou erro de digitação no cadastro. | J29: 1) Olhe a etiqueta do computador 1 do Carrinho 08. 2) Se o N/S for 09S29QAR700216: foi só erro de ditado. O sistema está certo; corrija o número na planilha. 3) Se o N/S for outro (como 09S29QBR700216N): o cadastro do sistema está errado. Avisar quem mantém o sistema. | K29: Não
A30: 26 | B30: Carrinho 08 | C30: 8 | D30: Erro provável de ditado | E30: 09S29QBR011410F | F30: 503696 | G30: 09S29QBR811410 | H30: Carrinho 08 - CINZA | I30: Foi ditado 011410, mas no sistema o Carrinho 08 tem 811410 (0 no lugar de 8). Provável erro de ditado. | J30: 1) Olhe a etiqueta do computador 8 do Carrinho 08. 2) Se o N/S for 09S29QBR811410: foi só erro de ditado. O sistema está certo; corrija o número na planilha. 3) Se o N/S for outro (como 09S29QBR011410F): o cadastro do sistema está errado. Avisar quem mantém o sistema. | K30: Não
A31: 27 | B31: Carrinho 08 | C31: 10 | D31: Local diferente no sistema | E31: 09S29QBR812708M | F31: 503623 | G31: 09S29QBR812708 | H31: Carrinho 11 - PRETO | I31: O N/S existe no sistema, mas o cadastro diz que ele está no Carrinho 11 - PRETO. Pode ter mudado de carrinho sem atualizar o sistema. | J31: 1) Confirme que o equipamento (N/S 09S29QBR812708) está mesmo no Carrinho 08. 2) Se estiver: atualizar a localização no sistema (hoje: Carrinho 11 - PRETO). 3) Se não estiver: foi erro na contagem. Descubra de qual carrinho ele é e corrija a lista. | K31: Não
A32: 28 | B32: Carrinho 08 | C32: — | D32: Sobra no sistema (não está no Word) | E32: — | F32: — | G32: 09S29QAR110966J | H32: Carrinho 08 - CINZA | I32: Está cadastrado no Carrinho 08, mas nenhum computador do Word tem esse N/S. Pode estar em outro carrinho, na manutenção ou faltando. Hipótese: foi trocado de carrinho com o 812708M (computador 10 do Carrinho 08, cadastrado no Carrinho 11). Confira isso quando fizer o Carrinho 11. Ele aparece no Word dos Chromebooks quebrados (computador 4), então provavelmente está lá e só falta atualizar a localização no sistema. | J32: 1) Procure o equipamento de N/S 09S29QAR110966J. 2) Se achar em outro carrinho ou na manutenção: atualizar a localização no sistema. 3) Se não achar em lugar nenhum: registrar como não localizado. | K32: Não
A33: 29 | B33: Carrinho 10 | C33: — | D33: Sobra no sistema (não está no Word) | E33: — | F33: — | G33: 09S29QBR722559 | H33: Carrinho 10 - MARROM | I33: Está cadastrado no Carrinho 10, mas nenhum computador do Word tem esse N/S (o Word tem 24 Chromebooks e o sistema tem 26). Hipótese: é um dos Samsung cinza entregues aos professores na troca pelo branco, como o 09S29QBR711970 do Carrinho 03. Confira com os professores. | J33: 1) Procure o equipamento de N/S 09S29QBR722559. 2) Se achar em outro carrinho ou na manutenção: atualizar a localização no sistema. 3) Se não achar em lugar nenhum: registrar como não localizado. | K33: Não
A34: 30 | B34: Carrinho 10 | C34: — | D34: Sobra no sistema (não está no Word) | E34: — | F34: — | G34: 09S29QBR702226 | H34: Carrinho 10 - MARROM | I34: Está cadastrado no Carrinho 10, mas nenhum computador do Word tem esse N/S (o Word tem 24 Chromebooks e o sistema tem 26). Hipótese: é um dos Samsung cinza entregues aos professores na troca pelo branco, como o 09S29QBR711970 do Carrinho 03. Confira com os professores. Ele aparece no Word dos Chromebooks quebrados (computador 6), então provavelmente está lá e só falta atualizar a localização no sistema. | J34: 1) Procure o equipamento de N/S 09S29QBR702226. 2) Se achar em outro carrinho ou na manutenção: atualizar a localização no sistema. 3) Se não achar em lugar nenhum: registrar como não localizado. | K34: Não
A35: 31 | B35: Carrinho 12 | C35: 1 | D35: Erro provável de ditado | E35: NXH0HAL001838E68C9501 | F35: 415274 | G35: NXH0HAL001838E68C29501 | H35: Carrinho 12 - OCRE | I35: Foi ditado NXH0HAL001838E68C9501, com 21 caracteres (falta o 2). No sistema o Carrinho 12 tem NXH0HAL001838E68C29501. Deve ser o mesmo equipamento. | J35: 1) Olhe a etiqueta do computador 1 do Carrinho 12. 2) Se o N/S for NXH0HAL001838E68C29501: foi só erro de ditado. O sistema está certo; corrija o número na planilha. 3) Se o N/S for outro (como NXH0HAL001838E68C9501): o cadastro do sistema está errado. Avisar quem mantém o sistema. | K35: Não
A36: 32 | B36: Carrinho 12 | C36: 12 | D36: Erro provável de ditado | E36: NXH0HAL001830EDC819501 | F36: 416497 | G36: NXH0HAL001839EDC819501 | H36: Carrinho 12 - OCRE | I36: Foi ditado NXH0HAL001830EDC819501, com 0 no lugar de 9. No sistema o Carrinho 12 tem NXH0HAL001839EDC819501. Deve ser o mesmo equipamento. | J36: 1) Olhe a etiqueta do computador 12 do Carrinho 12. 2) Se o N/S for NXH0HAL001839EDC819501: foi só erro de ditado. O sistema está certo; corrija o número na planilha. 3) Se o N/S for outro (como NXH0HAL001830EDC819501): o cadastro do sistema está errado. Avisar quem mantém o sistema. | K36: Não
A37: 33 | B37: Carrinho 12 | C37: — | D37: Sobra no sistema (não está no Word) | E37: — | F37: — | G37: NXH0HAL001838E7BC19501 | H37: Carrinho 12 - OCRE | I37: Está cadastrado no Carrinho 12, mas nenhum computador do Word tem esse N/S. Pode estar em outro carrinho que ainda não foi conferido ou ter mudado de lugar sem atualizar o sistema. Confira quando chegar aos carrinhos 09, 11 e 13. Ele aparece no Word dos Chromebooks quebrados (computador 27), então provavelmente está lá e só falta atualizar a localização no sistema. | J37: 1) Procure o equipamento de N/S NXH0HAL001838E7BC19501. 2) Se achar em outro carrinho ou na manutenção: atualizar a localização no sistema. 3) Se não achar em lugar nenhum: registrar como não localizado. | K37: Não
A38: 34 | B38: Carrinho 12 | C38: — | D38: Sobra no sistema (não está no Word) | E38: — | F38: — | G38: NXH0HAL001838E71669501 | H38: Carrinho 12 - OCRE | I38: Está cadastrado no Carrinho 12, mas nenhum computador do Word tem esse N/S. Pode estar em outro carrinho que ainda não foi conferido ou ter mudado de lugar sem atualizar o sistema. Confira quando chegar aos carrinhos 09, 11 e 13. Ele aparece no Word dos Chromebooks quebrados (computador 24), então provavelmente está lá e só falta atualizar a localização no sistema. | J38: 1) Procure o equipamento de N/S NXH0HAL001838E71669501. 2) Se achar em outro carrinho ou na manutenção: atualizar a localização no sistema. 3) Se não achar em lugar nenhum: registrar como não localizado. | K38: Não
A39: 35 | B39: Carrinho 12 | C39: — | D39: Sobra no sistema (não está no Word) | E39: — | F39: — | G39: NXH0HAL001838E76A89501 | H39: Carrinho 12 - OCRE | I39: Está cadastrado no Carrinho 12, mas nenhum computador do Word tem esse N/S. Pode estar em outro carrinho que ainda não foi conferido ou ter mudado de lugar sem atualizar o sistema. Confira quando chegar aos carrinhos 09, 11 e 13. Ele aparece no Word dos Chromebooks quebrados (computador 19), então provavelmente está lá e só falta atualizar a localização no sistema. | J39: 1) Procure o equipamento de N/S NXH0HAL001838E76A89501. 2) Se achar em outro carrinho ou na manutenção: atualizar a localização no sistema. 3) Se não achar em lugar nenhum: registrar como não localizado. | K39: Não
A40: 36 | B40: Carrinho 11 | C40: — | D40: Sobra no sistema (não está no Word) | E40: — | F40: — | G40: 09S29QBR812708 | H40: Carrinho 11 - PRETO | I40: Está cadastrado no Carrinho 11, mas nenhum computador do Word tem esse N/S. Pode estar com um professor (troca do branco pelo cinza) ou em um carrinho ainda não conferido (09, 13, reserva). Confira fisicamente. | J40: 1) Procure o equipamento de N/S 09S29QBR812708. 2) Se achar em outro carrinho ou na manutenção: atualizar a localização no sistema. 3) Se não achar em lugar nenhum: registrar como não localizado. | K40: Não
A41: 37 | B41: Carrinho 11 | C41: — | D41: Sobra no sistema (não está no Word) | E41: — | F41: — | G41: 09S29QBR712220 | H41: Carrinho 11 - PRETO | I41: Está cadastrado no Carrinho 11, mas nenhum computador do Word tem esse N/S. Pode estar com um professor (troca do branco pelo cinza) ou em um carrinho ainda não conferido (09, 13, reserva). Confira fisicamente. Ele aparece no Word dos Chromebooks quebrados (computador 3), então provavelmente está lá e só falta atualizar a localização no sistema. | J41: 1) Procure o equipamento de N/S 09S29QBR712220. 2) Se achar em outro carrinho ou na manutenção: atualizar a localização no sistema. 3) Se não achar em lugar nenhum: registrar como não localizado. | K41: Não
...

Sheet Conferência
A1: Inventário de Chromebooks – Conferência Word x Sistema da prefeitura
A3: Carrinho (Word) | B3: Nº | C3: N/S ditado (sem espaços) | D3: Chave de comparação | E3: Letra final (Word) | F3: Patrimônio (Word) | G3: Modelo informado | H3: Local no sistema | I3: Modelo no sistema | J3: Letra final (sistema) | K3: Situação | L3: Observação | M3: Estado informado no Word
A4: Carrinho 01 ( AZUL) | B4: 1 | C4: NXH0HAL001832D5BB39501 | D4: =IF(LEFT(C4,3)="09S",LEFT(C4,14),C4) -> NXH0HAL001832D5BB39501 | E4: =IF(LEFT(C4,3)="09S",MID(C4,15,5),"") | F4: 413984 | G4: Acer Chromebook 11 C731 (N16Q13) preto | H4: =IFERROR(INDEX(Sistema!$F$2:$F$421,MATCH(D4,Sistema!$G$2:$G$421,0)),"Não encontrado") -> Carrinho 01 ( AZUL) | I4: =IFERROR(INDEX(Sistema!$C$2:$C$421,MATCH(D4,Sistema!$G$2:$G$421,0)),"") -> Acer Chromebook 11 N7 (C731, C731T) | J4: =IF(LEFT(C4,3)="09S",IFERROR(MID(INDEX(Sistema!$D$2:$D$421,MATCH(D4,Sistema!$G$2:$G$421,0)),15,5),""),"") | K4: =IF(H4="Não encontrado","Não encontrado",IF(H4<>A4,"Local diferente",IF(AND(E4<>"",J4<>"",UPPER(E4)<>UPPER(J4)),"Letra final diferente","Confere"))) -> Confere
A5: Carrinho 01 ( AZUL) | B5: 2 | C5: NXH0HAL001832D69D19501 | D5: =IF(LEFT(C5,3)="09S",LEFT(C5,14),C5) -> NXH0HAL001832D69D19501 | E5: =IF(LEFT(C5,3)="09S",MID(C5,15,5),"") | F5: 413920 | G5: Acer Chromebook 11 C731 (N16Q13) preto | H5: =IFERROR(INDEX(Sistema!$F$2:$F$421,MATCH(D5,Sistema!$G$2:$G$421,0)),"Não encontrado") -> Carrinho 01 ( AZUL) | I5: =IFERROR(INDEX(Sistema!$C$2:$C$421,MATCH(D5,Sistema!$G$2:$G$421,0)),"") -> Acer Chromebook 11 N7 (C731, C731T) | J5: =IF(LEFT(C5,3)="09S",IFERROR(MID(INDEX(Sistema!$D$2:$D$421,MATCH(D5,Sistema!$G$2:$G$421,0)),15,5),""),"") | K5: =IF(H5="Não encontrado","Não encontrado",IF(H5<>A5,"Local diferente",IF(AND(E5<>"",J5<>"",UPPER(E5)<>UPPER(J5)),"Letra final diferente","Confere"))) -> Confere
A6: Carrinho 01 ( AZUL) | B6: 3 | C6: NXH0HAL001832D60FE9501 | D6: =IF(LEFT(C6,3)="09S",LEFT(C6,14),C6) -> NXH0HAL001832D60FE9501 | E6: =IF(LEFT(C6,3)="09S",MID(C6,15,5),"") | F6: 413910 | G6: Acer Chromebook 11 C731 (N16Q13) preto | H6: =IFERROR(INDEX(Sistema!$F$2:$F$421,MATCH(D6,Sistema!$G$2:$G$421,0)),"Não encontrado") -> Carrinho 01 ( AZUL) | I6: =IFERROR(INDEX(Sistema!$C$2:$C$421,MATCH(D6,Sistema!$G$2:$G$421,0)),"") -> Acer Chromebook 11 N7 (C731, C731T) | J6: =IF(LEFT(C6,3)="09S",IFERROR(MID(INDEX(Sistema!$D$2:$D$421,MATCH(D6,Sistema!$G$2:$G$421,0)),15,5),""),"") | K6: =IF(H6="Não encontrado","Não encontrado",IF(H6<>A6,"Local diferente",IF(AND(E6<>"",J6<>"",UPPER(E6)<>UPPER(J6)),"Letra final diferente","Confere"))) -> Confere
A7: Carrinho 01 ( AZUL) | B7: 4 | C7: NXH0HAL001832D659F9501 | D7: =IF(LEFT(C7,3)="09S",LEFT(C7,14),C7) -> NXH0HAL001832D659F9501 | E7: =IF(LEFT(C7,3)="09S",MID(C7,15,5),"") | F7: 413798 | G7: Acer Chromebook 11 C731 (N16Q13) preto | H7: =IFERROR(INDEX(Sistema!$F$2:$F$421,MATCH(D7,Sistema!$G$2:$G$421,0)),"Não encontrado") -> Carrinho 01 ( AZUL) | I7: =IFERROR(INDEX(Sistema!$C$2:$C$421,MATCH(D7,Sistema!$G$2:$G$421,0)),"") -> Acer Chromebook 11 N7 (C731, C731T) | J7: =IF(LEFT(C7,3)="09S",IFERROR(MID(INDEX(Sistema!$D$2:$D$421,MATCH(D7,Sistema!$G$2:$G$421,0)),15,5),""),"") | K7: =IF(H7="Não encontrado","Não encontrado",IF(H7<>A7,"Local diferente",IF(AND(E7<>"",J7<>"",UPPER(E7)<>UPPER(J7)),"Letra final diferente","Confere"))) -> Confere
A8: Carrinho 01 ( AZUL) | B8: 5 | C8: NXH0HAL001839ECE489501 | D8: =IF(LEFT(C8,3)="09S",LEFT(C8,14),C8) -> NXH0HAL001839ECE489501 | E8: =IF(LEFT(C8,3)="09S",MID(C8,15,5),"") | F8: 413962 | G8: Acer Chromebook 11 C731 (N16Q13) preto | H8: =IFERROR(INDEX(Sistema!$F$2:$F$421,MATCH(D8,Sistema!$G$2:$G$421,0)),"Não encontrado") -> Carrinho 01 ( AZUL) | I8: =IFERROR(INDEX(Sistema!$C$2:$C$421,MATCH(D8,Sistema!$G$2:$G$421,0)),"") -> Acer Chromebook 11 N7 (C731, C731T) | J8: =IF(LEFT(C8,3)="09S",IFERROR(MID(INDEX(Sistema!$D$2:$D$421,MATCH(D8,Sistema!$G$2:$G$421,0)),15,5),""),"") | K8: =IF(H8="Não encontrado","Não encontrado",IF(H8<>A8,"Local diferente",IF(AND(E8<>"",J8<>"",UPPER(E8)<>UPPER(J8)),"Letra final diferente","Confere"))) -> Confere
A9: Carrinho 01 ( AZUL) | B9: 6 | C9: NXH0HAL001832D69CD9501 | D9: =IF(LEFT(C9,3)="09S",LEFT(C9,14),C9) -> NXH0HAL001832D69CD9501 | E9: =IF(LEFT(C9,3)="09S",MID(C9,15,5),"") | F9: 413766 | G9: Acer Chromebook 11 C731 (N16Q13) preto | H9: =IFERROR(INDEX(Sistema!$F$2:$F$421,MATCH(D9,Sistema!$G$2:$G$421,0)),"Não encontrado") -> Carrinho 01 ( AZUL) | I9: =IFERROR(INDEX(Sistema!$C$2:$C$421,MATCH(D9,Sistema!$G$2:$G$421,0)),"") -> Acer Chromebook 11 N7 (C731, C731T) | J9: =IF(LEFT(C9,3)="09S",IFERROR(MID(INDEX(Sistema!$D$2:$D$421,MATCH(D9,Sistema!$G$2:$G$421,0)),15,5),""),"") | K9: =IF(H9="Não encontrado","Não encontrado",IF(H9<>A9,"Local diferente",IF(AND(E9<>"",J9<>"",UPPER(E9)<>UPPER(J9)),"Letra final diferente","Confere"))) -> Confere
A10: Carrinho 01 ( AZUL) | B10: 7 | C10: NXH0HAL001832D65869501 | D10: =IF(LEFT(C10,3)="09S",LEFT(C10,14),C10) -> NXH0HAL001832D65869501 | E10: =IF(LEFT(C10,3)="09S",MID(C10,15,5),"") | F10: 413918 | G10: Acer Chromebook 11 C731 (N16Q13) preto | H10: =IFERROR(INDEX(Sistema!$F$2:$F$421,MATCH(D10,Sistema!$G$2:$G$421,0)),"Não encontrado") -> Carrinho 01 ( AZUL) | I10: =IFERROR(INDEX(Sistema!$C$2:$C$421,MATCH(D10,Sistema!$G$2:$G$421,0)),"") -> Acer Chromebook 11 N7 (C731, C731T) | J10: =IF(LEFT(C10,3)="09S",IFERROR(MID(INDEX(Sistema!$D$2:$D$421,MATCH(D10,Sistema!$G$2:$G$421,0)),15,5),""),"") | K10: =IF(H10="Não encontrado","Não encontrado",IF(H10<>A10,"Local diferente",IF(AND(E10<>"",J10<>"",UPPER(E10)<>UPPER(J10)),"Letra final diferente","Confere"))) -> Confere
A11: Carrinho 01 ( AZUL) | B11: 8 | C11: NXH0HAL001832D68659501 | D11: =IF(LEFT(C11,3)="09S",LEFT(C11,14),C11) -> NXH0HAL001832D68659501 | E11: =IF(LEFT(C11,3)="09S",MID(C11,15,5),"") | F11: 413875 | G11: Acer Chromebook 11 C731 (N16Q13) preto | H11: =IFERROR(INDEX(Sistema!$F$2:$F$421,MATCH(D11,Sistema!$G$2:$G$421,0)),"Não encontrado") -> Carrinho 01 ( AZUL) | I11: =IFERROR(INDEX(Sistema!$C$2:$C$421,MATCH(D11,Sistema!$G$2:$G$421,0)),"") -> Acer Chromebook 11 N7 (C731, C731T) | J11: =IF(LEFT(C11,3)="09S",IFERROR(MID(INDEX(Sistema!$D$2:$D$421,MATCH(D11,Sistema!$G$2:$G$421,0)),15,5),""),"") | K11: =IF(H11="Não encontrado","Não encontrado",IF(H11<>A11,"Local diferente",IF(AND(E11<>"",J11<>"",UPPER(E11)<>UPPER(J11)),"Letra final diferente","Confere"))) -> Confere
A12: Carrinho 01 ( AZUL) | B12: 9 | C12: NXH0HAL001832D65DD9501 | D12: =IF(LEFT(C12,3)="09S",LEFT(C12,14),C12) -> NXH0HAL001832D65DD9501 | E12: =IF(LEFT(C12,3)="09S",MID(C12,15,5),"") | F12: 413890 | G12: Acer Chromebook 11 C731 (N16Q13) preto | H12: =IFERROR(INDEX(Sistema!$F$2:$F$421,MATCH(D12,Sistema!$G$2:$G$421,0)),"Não encontrado") -> Carrinho 01 ( AZUL) | I12: =IFERROR(INDEX(Sistema!$C$2:$C$421,MATCH(D12,Sistema!$G$2:$G$421,0)),"") -> Acer Chromebook 11 N7 (C731, C731T) | J12: =IF(LEFT(C12,3)="09S",IFERROR(MID(INDEX(Sistema!$D$2:$D$421,MATCH(D12,Sistema!$G$2:$G$421,0)),15,5),""),"") | K12: =IF(H12="Não encontrado","Não encontrado",IF(H12<>A12,"Local diferente",IF(AND(E12<>"",J12<>"",UPPER(E12)<>UPPER(J12)),"Letra final diferente","Confere"))) -> Confere
A13: Carrinho 01 ( AZUL) | B13: 10 | C13: NXH0HAL001832D65E79501 | D13: =IF(LEFT(C13,3)="09S",LEFT(C13,14),C13) -> NXH0HAL001832D65E79501 | E13: =IF(LEFT(C13,3)="09S",MID(C13,15,5),"") | F13: 413802 | G13: Acer Chromebook 11 C731 (N16Q13) preto | H13: =IFERROR(INDEX(Sistema!$F$2:$F$421,MATCH(D13,Sistema!$G$2:$G$421,0)),"Não encontrado") -> Carrinho 01 ( AZUL) | I13: =IFERROR(INDEX(Sistema!$C$2:$C$421,MATCH(D13,Sistema!$G$2:$G$421,0)),"") -> Acer Chromebook 11 N7 (C731, C731T) | J13: =IF(LEFT(C13,3)="09S",IFERROR(MID(INDEX(Sistema!$D$2:$D$421,MATCH(D13,Sistema!$G$2:$G$421,0)),15,5),""),"") | K13: =IF(H13="Não encontrado","Não encontrado",IF(H13<>A13,"Local diferente",IF(AND(E13<>"",J13<>"",UPPER(E13)<>UPPER(J13)),"Letra final diferente","Confere"))) -> Confere
A14: Carrinho 01 ( AZUL) | B14: 11 | C14: NXH0HAL001832D68A59501 | D14: =IF(LEFT(C14,3)="09S",LEFT(C14,14),C14) -> NXH0HAL001832D68A59501 | E14: =IF(LEFT(C14,3)="09S",MID(C14,15,5),"") | F14: 413902 | G14: Acer Chromebook 11 C731 (N16Q13) preto | H14: =IFERROR(INDEX(Sistema!$F$2:$F$421,MATCH(D14,Sistema!$G$2:$G$421,0)),"Não encontrado") -> Carrinho 01 ( AZUL) | I14: =IFERROR(INDEX(Sistema!$C$2:$C$421,MATCH(D14,Sistema!$G$2:$G$421,0)),"") -> Acer Chromebook 11 N7 (C731, C731T) | J14: =IF(LEFT(C14,3)="09S",IFERROR(MID(INDEX(Sistema!$D$2:$D$421,MATCH(D14,Sistema!$G$2:$G$421,0)),15,5),""),"") | K14: =IF(H14="Não encontrado","Não encontrado",IF(H14<>A14,"Local diferente",IF(AND(E14<>"",J14<>"",UPPER(E14)<>UPPER(J14)),"Letra final diferente","Confere"))) -> Confere
A15: Carrinho 01 ( AZUL) | B15: 12 | C15: NXH0HAL001830D20719501 | D15: =IF(LEFT(C15,3)="09S",LEFT(C15,14),C15) -> NXH0HAL001830D20719501 | E15: =IF(LEFT(C15,3)="09S",MID(C15,15,5),"") | F15: 413983 | G15: Acer Chromebook 11 C731 (N16Q13) preto | H15: =IFERROR(INDEX(Sistema!$F$2:$F$421,MATCH(D15,Sistema!$G$2:$G$421,0)),"Não encontrado") -> Não encontrado | I15: =IFERROR(INDEX(Sistema!$C$2:$C$421,MATCH(D15,Sistema!$G$2:$G$421,0)),"") | J15: =IF(LEFT(C15,3)="09S",IFERROR(MID(INDEX(Sistema!$D$2:$D$421,MATCH(D15,Sistema!$G$2:$G$421,0)),15,5),""),"") | K15: =IF(H15="Não encontrado","Não encontrado",IF(H15<>A15,"Local diferente",IF(AND(E15<>"",J15<>"",UPPER(E15)<>UPPER(J15)),"Letra final diferente","Confere"))) -> Não encontrado | L15: Ditado NXH0HAL001830D20719501. Esse N/S não existe no sistema e não é parecido com nenhum dos que sobram no Carrinho 01. Pode ser erro de ditado maior ou equipamento não cadastrado: conferir a etiqueta.
A16: Carrinho 01 ( AZUL) | B16: 13 | C16: NXH0HAL001838E766E9501 | D16: =IF(LEFT(C16,3)="09S",LEFT(C16,14),C16) -> NXH0HAL001838E766E9501 | E16: =IF(LEFT(C16,3)="09S",MID(C16,15,5),"") | F16: 412369 | G16: Acer Chromebook 11 C731 (N16Q13) preto | H16: =IFERROR(INDEX(Sistema!$F$2:$F$421,MATCH(D16,Sistema!$G$2:$G$421,0)),"Não encontrado") -> Carrinho 01 ( AZUL) | I16: =IFERROR(INDEX(Sistema!$C$2:$C$421,MATCH(D16,Sistema!$G$2:$G$421,0)),"") -> Acer Chromebook 11 N7 (C731, C731T) | J16: =IF(LEFT(C16,3)="09S",IFERROR(MID(INDEX(Sistema!$D$2:$D$421,MATCH(D16,Sistema!$G$2:$G$421,0)),15,5),""),"") | K16: =IF(H16="Não encontrado","Não encontrado",IF(H16<>A16,"Local diferente",IF(AND(E16<>"",J16<>"",UPPER(E16)<>UPPER(J16)),"Letra final diferente","Confere"))) -> Confere
A17: Carrinho 01 ( AZUL) | B17: 14 | C17: NXH0HAL001832D65BF9501 | D17: =IF(LEFT(C17,3)="09S",LEFT(C17,14),C17) -> NXH0HAL001832D65BF9501 | E17: =IF(LEFT(C17,3)="09S",MID(C17,15,5),"") | F17: 413911 | G17: Acer Chromebook 11 C731 (N16Q13) preto | H17: =IFERROR(INDEX(Sistema!$F$2:$F$421,MATCH(D17,Sistema!$G$2:$G$421,0)),"Não encontrado") -> Carrinho 01 ( AZUL) | I17: =IFERROR(INDEX(Sistema!$C$2:$C$421,MATCH(D17,Sistema!$G$2:$G$421,0)),"") -> Acer Chromebook 11 N7 (C731, C731T) | J17: =IF(LEFT(C17,3)="09S",IFERROR(MID(INDEX(Sistema!$D$2:$D$421,MATCH(D17,Sistema!$G$2:$G$421,0)),15,5),""),"") | K17: =IF(H17="Não encontrado","Não encontrado",IF(H17<>A17,"Local diferente",IF(AND(E17<>"",J17<>"",UPPER(E17)<>UPPER(J17)),"Letra final diferente","Confere"))) -> Confere
A18: Carrinho 01 ( AZUL) | B18: 15 | C18: NXH0HAL001832D65439501 | D18: =IF(LEFT(C18,3)="09S",LEFT(C18,14),C18) -> NXH0HAL001832D65439501 | E18: =IF(LEFT(C18,3)="09S",MID(C18,15,5),"") | F18: 413900 | G18: Acer Chromebook 11 C731 (N16Q13) preto | H18: =IFERROR(INDEX(Sistema!$F$2:$F$421,MATCH(D18,Sistema!$G$2:$G$421,0)),"Não encontrado") -> Carrinho 01 ( AZUL) | I18: =IFERROR(INDEX(Sistema!$C$2:$C$421,MATCH(D18,Sistema!$G$2:$G$421,0)),"") -> Acer Chromebook 11 N7 (C731, C731T) | J18: =IF(LEFT(C18,3)="09S",IFERROR(MID(INDEX(Sistema!$D$2:$D$421,MATCH(D18,Sistema!$G$2:$G$421,0)),15,5),""),"") | K18: =IF(H18="Não encontrado","Não encontrado",IF(H18<>A18,"Local diferente",IF(AND(E18<>"",J18<>"",UPPER(E18)<>UPPER(J18)),"Letra final diferente","Confere"))) -> Confere
A19: Carrinho 01 ( AZUL) | B19: 16 | C19: NXH0HAL001832D58349501 | D19: =IF(LEFT(C19,3)="09S",LEFT(C19,14),C19) -> NXH0HAL001832D58349501 | E19: =IF(LEFT(C19,3)="09S",MID(C19,15,5),"") | F19: 413961 | G19: Acer Chromebook 11 C731 (N16Q13) preto | H19: =IFERROR(INDEX(Sistema!$F$2:$F$421,MATCH(D19,Sistema!$G$2:$G$421,0)),"Não encontrado") -> Carrinho 01 ( AZUL) | I19: =IFERROR(INDEX(Sistema!$C$2:$C$421,MATCH(D19,Sistema!$G$2:$G$421,0)),"") -> Acer Chromebook 11 N7 (C731, C731T) | J19: =IF(LEFT(C19,3)="09S",IFERROR(MID(INDEX(Sistema!$D$2:$D$421,MATCH(D19,Sistema!$G$2:$G$421,0)),15,5),""),"") | K19: =IF(H19="Não encontrado","Não encontrado",IF(H19<>A19,"Local diferente",IF(AND(E19<>"",J19<>"",UPPER(E19)<>UPPER(J19)),"Letra final diferente","Confere"))) -> Confere
A20: Carrinho 01 ( AZUL) | B20: 17 | C20: NXH0HAL001832D61879501 | D20: =IF(LEFT(C20,3)="09S",LEFT(C20,14),C20) -> NXH0HAL001832D61879501 | E20: =IF(LEFT(C20,3)="09S",MID(C20,15,5),"") | F20: 413917 | G20: Acer Chromebook 11 C731 (N16Q13) preto | H20: =IFERROR(INDEX(Sistema!$F$2:$F$421,MATCH(D20,Sistema!$G$2:$G$421,0)),"Não encontrado") -> Carrinho 01 ( AZUL) | I20: =IFERROR(INDEX(Sistema!$C$2:$C$421,MATCH(D20,Sistema!$G$2:$G$421,0)),"") -> Acer Chromebook 11 N7 (C731, C731T) | J20: =IF(LEFT(C20,3)="09S",IFERROR(MID(INDEX(Sistema!$D$2:$D$421,MATCH(D20,Sistema!$G$2:$G$421,0)),15,5),""),"") | K20: =IF(H20="Não encontrado","Não encontrado",IF(H20<>A20,"Local diferente",IF(AND(E20<>"",J20<>"",UPPER(E20)<>UPPER(J20)),"Letra final diferente","Confere"))) -> Confere
A21: Carrinho 01 ( AZUL) | B21: 18 | C21: NXH0HAL001830D20939501 | D21: =IF(LEFT(C21,3)="09S",LEFT(C21,14),C21) -> NXH0HAL001830D20939501 | E21: =IF(LEFT(C21,3)="09S",MID(C21,15,5),"") | F21: 413966 | G21: Acer Chromebook 11 C731 (N16Q13) preto | H21: =IFERROR(INDEX(Sistema!$F$2:$F$421,MATCH(D21,Sistema!$G$2:$G$421,0)),"Não encontrado") -> Carrinho 01 ( AZUL) | I21: =IFERROR(INDEX(Sistema!$C$2:$C$421,MATCH(D21,Sistema!$G$2:$G$421,0)),"") -> Acer Chromebook 11 N7 (C731, C731T) | J21: =IF(LEFT(C21,3)="09S",IFERROR(MID(INDEX(Sistema!$D$2:$D$421,MATCH(D21,Sistema!$G$2:$G$421,0)),15,5),""),"") | K21: =IF(H21="Não encontrado","Não encontrado",IF(H21<>A21,"Local diferente",IF(AND(E21<>"",J21<>"",UPPER(E21)<>UPPER(J21)),"Letra final diferente","Confere"))) -> Confere
A22: Carrinho 01 ( AZUL) | B22: 19 | C22: NXH0HAL001839ED5D19501 | D22: =IF(LEFT(C22,3)="09S",LEFT(C22,14),C22) -> NXH0HAL001839ED5D19501 | E22: =IF(LEFT(C22,3)="09S",MID(C22,15,5),"") | F22: 413975 | G22: Acer Chromebook 11 C731 (N16Q13) preto | H22: =IFERROR(INDEX(Sistema!$F$2:$F$421,MATCH(D22,Sistema!$G$2:$G$421,0)),"Não encontrado") -> Carrinho 01 ( AZUL) | I22: =IFERROR(INDEX(Sistema!$C$2:$C$421,MATCH(D22,Sistema!$G$2:$G$421,0)),"") -> Acer Chromebook 11 N7 (C731, C731T) | J22: =IF(LEFT(C22,3)="09S",IFERROR(MID(INDEX(Sistema!$D$2:$D$421,MATCH(D22,Sistema!$G$2:$G$421,0)),15,5),""),"") | K22: =IF(H22="Não encontrado","Não encontrado",IF(H22<>A22,"Local diferente",IF(AND(E22<>"",J22<>"",UPPER(E22)<>UPPER(J22)),"Letra final diferente","Confere"))) -> Confere
A23: Carrinho 01 ( AZUL) | B23: 20 | C23: NXH0HAL001832DD66639501 | D23: =IF(LEFT(C23,3)="09S",LEFT(C23,14),C23) -> NXH0HAL001832DD66639501 | E23: =IF(LEFT(C23,3)="09S",MID(C23,15,5),"") | F23: 413913 | G23: Acer Chromebook 11 C731 (N16Q13) preto | H23: =IFERROR(INDEX(Sistema!$F$2:$F$421,MATCH(D23,Sistema!$G$2:$G$421,0)),"Não encontrado") -> Não encontrado | I23: =IFERROR(INDEX(Sistema!$C$2:$C$421,MATCH(D23,Sistema!$G$2:$G$421,0)),"") | J23: =IF(LEFT(C23,3)="09S",IFERROR(MID(INDEX(Sistema!$D$2:$D$421,MATCH(D23,Sistema!$G$2:$G$421,0)),15,5),""),"") | K23: =IF(H23="Não encontrado","Não encontrado",IF(H23<>A23,"Local diferente",IF(AND(E23<>"",J23<>"",UPPER(E23)<>UPPER(J23)),"Letra final diferente","Confere"))) -> Não encontrado | L23: Ditado com 23 caracteres (um D a mais: NXH0HAL001832DD66639501). No sistema o Carrinho 01 tem NXH0HAL001832D66639501. Provável erro de ditado: conferir a etiqueta.
A24: Carrinho 01 ( AZUL) | B24: 21 | C24: NXH0HAL001830D1F729501 | D24: =IF(LEFT(C24,3)="09S",LEFT(C24,14),C24) -> NXH0HAL001830D1F729501 | E24: =IF(LEFT(C24,3)="09S",MID(C24,15,5),"") | F24: 414349 | G24: Acer Chromebook 11 C731 (N16Q13) preto | H24: =IFERROR(INDEX(Sistema!$F$2:$F$421,MATCH(D24,Sistema!$G$2:$G$421,0)),"Não encontrado") -> Carrinho 01 ( AZUL) | I24: =IFERROR(INDEX(Sistema!$C$2:$C$421,MATCH(D24,Sistema!$G$2:$G$421,0)),"") -> Acer Chromebook 11 N7 (C731, C731T) | J24: =IF(LEFT(C24,3)="09S",IFERROR(MID(INDEX(Sistema!$D$2:$D$421,MATCH(D24,Sistema!$G$2:$G$421,0)),15,5),""),"") | K24: =IF(H24="Não encontrado","Não encontrado",IF(H24<>A24,"Local diferente",IF(AND(E24<>"",J24<>"",UPPER(E24)<>UPPER(J24)),"Letra final diferente","Confere"))) -> Confere
A25: Carrinho 01 ( AZUL) | B25: 22 | C25: NXH0HAL001830D1F749501 | D25: =IF(LEFT(C25,3)="09S",LEFT(C25,14),C25) -> NXH0HAL001830D1F749501 | E25: =IF(LEFT(C25,3)="09S",MID(C25,15,5),"") | F25: 414368 | G25: Acer Chromebook 11 C731 (N16Q13) preto | H25: =IFERROR(INDEX(Sistema!$F$2:$F$421,MATCH(D25,Sistema!$G$2:$G$421,0)),"Não encontrado") -> Carrinho 01 ( AZUL) | I25: =IFERROR(INDEX(Sistema!$C$2:$C$421,MATCH(D25,Sistema!$G$2:$G$421,0)),"") -> Acer Chromebook 11 N7 (C731, C731T) | J25: =IF(LEFT(C25,3)="09S",IFERROR(MID(INDEX(Sistema!$D$2:$D$421,MATCH(D25,Sistema!$G$2:$G$421,0)),15,5),""),"") | K25: =IF(H25="Não encontrado","Não encontrado",IF(H25<>A25,"Local diferente",IF(AND(E25<>"",J25<>"",UPPER(E25)<>UPPER(J25)),"Letra final diferente","Confere"))) -> Confere
A26: Carrinho 01 ( AZUL) | B26: 23 | C26: NXH0HAL001830D1F949501 | D26: =IF(LEFT(C26,3)="09S",LEFT(C26,14),C26) -> NXH0HAL001830D1F949501 | E26: =IF(LEFT(C26,3)="09S",MID(C26,15,5),"") | F26: 414469 | G26: Acer Chromebook 11 C731 (N16Q13) preto | H26: =IFERROR(INDEX(Sistema!$F$2:$F$421,MATCH(D26,Sistema!$G$2:$G$421,0)),"Não encontrado") -> Carrinho 01 ( AZUL) | I26: =IFERROR(INDEX(Sistema!$C$2:$C$421,MATCH(D26,Sistema!$G$2:$G$421,0)),"") -> Acer Chromebook 11 N7 (C731, C731T) | J26: =IF(LEFT(C26,3)="09S",IFERROR(MID(INDEX(Sistema!$D$2:$D$421,MATCH(D26,Sistema!$G$2:$G$421,0)),15,5),""),"") | K26: =IF(H26="Não encontrado","Não encontrado",IF(H26<>A26,"Local diferente",IF(AND(E26<>"",J26<>"",UPPER(E26)<>UPPER(J26)),"Letra final diferente","Confere"))) -> Confere
A27: Carrinho 01 ( AZUL) | B27: 24 | C27: NXH0HAL001832D5B8F9501 | D27: =IF(LEFT(C27,3)="09S",LEFT(C27,14),C27) -> NXH0HAL001832D5B8F9501 | E27: =IF(LEFT(C27,3)="09S",MID(C27,15,5),"") | F27: 413955 | G27: Acer Chromebook 11 C731 (N16Q13) preto | H27: =IFERROR(INDEX(Sistema!$F$2:$F$421,MATCH(D27,Sistema!$G$2:$G$421,0)),"Não encontrado") -> Carrinho 01 ( AZUL) | I27: =IFERROR(INDEX(Sistema!$C$2:$C$421,MATCH(D27,Sistema!$G$2:$G$421,0)),"") -> Acer Chromebook 11 N7 (C731, C731T) | J27: =IF(LEFT(C27,3)="09S",IFERROR(MID(INDEX(Sistema!$D$2:$D$421,MATCH(D27,Sistema!$G$2:$G$421,0)),15,5),""),"") | K27: =IF(H27="Não encontrado","Não encontrado",IF(H27<>A27,"Local diferente",IF(AND(E27<>"",J27<>"",UPPER(E27)<>UPPER(J27)),"Letra final diferente","Confere"))) -> Confere
A28: Carrinho 01 ( AZUL) | B28: 25 | C28: NXH0HAL001832D687D9501 | D28: =IF(LEFT(C28,3)="09S",LEFT(C28,14),C28) -> NXH0HAL001832D687D9501 | E28: =IF(LEFT(C28,3)="09S",MID(C28,15,5),"") | F28: 413921 | G28: Acer Chromebook 11 C731 (N16Q13) preto | H28: =IFERROR(INDEX(Sistema!$F$2:$F$421,MATCH(D28,Sistema!$G$2:$G$421,0)),"Não encontrado") -> Carrinho 01 ( AZUL) | I28: =IFERROR(INDEX(Sistema!$C$2:$C$421,MATCH(D28,Sistema!$G$2:$G$421,0)),"") -> Acer Chromebook 11 N7 (C731, C731T) | J28: =IF(LEFT(C28,3)="09S",IFERROR(MID(INDEX(Sistema!$D$2:$D$421,MATCH(D28,Sistema!$G$2:$G$421,0)),15,5),""),"") | K28: =IF(H28="Não encontrado","Não encontrado",IF(H28<>A28,"Local diferente",IF(AND(E28<>"",J28<>"",UPPER(E28)<>UPPER(J28)),"Letra final diferente","Confere"))) -> Confere
A29: Carrinho 01 ( AZUL) | B29: 26 | C29: NXH0HAL001830D1BEA9501 | D29: =IF(LEFT(C29,3)="09S",LEFT(C29,14),C29) -> NXH0HAL001830D1BEA9501 | E29: =IF(LEFT(C29,3)="09S",MID(C29,15,5),"") | F29: 414534 | G29: Acer Chromebook 11 C731 (N16Q13) preto | H29: =IFERROR(INDEX(Sistema!$F$2:$F$421,MATCH(D29,Sistema!$G$2:$G$421,0)),"Não encontrado") -> Carrinho 01 ( AZUL) | I29: =IFERROR(INDEX(Sistema!$C$2:$C$421,MATCH(D29,Sistema!$G$2:$G$421,0)),"") -> Acer Chromebook 11 N7 (C731, C731T) | J29: =IF(LEFT(C29,3)="09S",IFERROR(MID(INDEX(Sistema!$D$2:$D$421,MATCH(D29,Sistema!$G$2:$G$421,0)),15,5),""),"") | K29: =IF(H29="Não encontrado","Não encontrado",IF(H29<>A29,"Local diferente",IF(AND(E29<>"",J29<>"",UPPER(E29)<>UPPER(J29)),"Letra final diferente","Confere"))) -> Confere
A30: Carrinho 01 ( AZUL) | B30: 27 | C30: NXH0HAL001832D65B89501 | D30: =IF(LEFT(C30,3)="09S",LEFT(C30,14),C30) -> NXH0HAL001832D65B89501 | E30: =IF(LEFT(C30,3)="09S",MID(C30,15,5),"") | F30: 413877 | G30: Acer Chromebook 11 C731 (N16Q13) preto | H30: =IFERROR(INDEX(Sistema!$F$2:$F$421,MATCH(D30,Sistema!$G$2:$G$421,0)),"Não encontrado") -> Carrinho 01 ( AZUL) | I30: =IFERROR(INDEX(Sistema!$C$2:$C$421,MATCH(D30,Sistema!$G$2:$G$421,0)),"") -> Acer Chromebook 11 N7 (C731, C731T) | J30: =IF(LEFT(C30,3)="09S",IFERROR(MID(INDEX(Sistema!$D$2:$D$421,MATCH(D30,Sistema!$G$2:$G$421,0)),15,5),""),"") | K30: =IF(H30="Não encontrado","Não encontrado",IF(H30<>A30,"Local diferente",IF(AND(E30<>"",J30<>"",UPPER(E30)<>UPPER(J30)),"Letra final diferente","Confere"))) -> Confere
A31: Carrinho 01 ( AZUL) | B31: 28 | C31: NXH0HAL0018481FB349501 | D31: =IF(LEFT(C31,3)="09S",LEFT(C31,14),C31) -> NXH0HAL0018481FB349501 | E31: =IF(LEFT(C31,3)="09S",MID(C31,15,5),"") | F31: 413813 | G31: Acer Chromebook 11 C731 (N16Q13) preto | H31: =IFERROR(INDEX(Sistema!$F$2:$F$421,MATCH(D31,Sistema!$G$2:$G$421,0)),"Não encontrado") -> Carrinho 01 ( AZUL) | I31: =IFERROR(INDEX(Sistema!$C$2:$C$421,MATCH(D31,Sistema!$G$2:$G$421,0)),"") -> Acer Chromebook 11 N7 (C731, C731T) | J31: =IF(LEFT(C31,3)="09S",IFERROR(MID(INDEX(Sistema!$D$2:$D$421,MATCH(D31,Sistema!$G$2:$G$421,0)),15,5),""),"") | K31: =IF(H31="Não encontrado","Não encontrado",IF(H31<>A31,"Local diferente",IF(AND(E31<>"",J31<>"",UPPER(E31)<>UPPER(J31)),"Letra final diferente","Confere"))) -> Confere
A32: Carrinho 02 ( AMARELO) | B32: 1 | C32: NXH0HAL001832D67269501 | D32: =IF(LEFT(C32,3)="09S",LEFT(C32,14),C32) -> NXH0HAL001832D67269501 | E32: =IF(LEFT(C32,3)="09S",MID(C32,15,5),"") | F32: 413919 | G32: Acer Chromebook 11 C731 (N16Q13) preto | H32: =IFERROR(INDEX(Sistema!$F$2:$F$421,MATCH(D32,Sistema!$G$2:$G$421,0)),"Não encontrado") -> Carrinho 02 ( AMARELO) | I32: =IFERROR(INDEX(Sistema!$C$2:$C$421,MATCH(D32,Sistema!$G$2:$G$421,0)),"") -> Acer Chromebook 11 N7 (C731, C731T) | J32: =IF(LEFT(C32,3)="09S",IFERROR(MID(INDEX(Sistema!$D$2:$D$421,MATCH(D32,Sistema!$G$2:$G$421,0)),15,5),""),"") | K32: =IF(H32="Não encontrado","Não encontrado",IF(H32<>A32,"Local diferente",IF(AND(E32<>"",J32<>"",UPPER(E32)<>UPPER(J32)),"Letra final diferente","Confere"))) -> Confere
A33: Carrinho 02 ( AMARELO) | B33: 2 | C33: NXH0HAL001832D5D789501 | D33: =IF(LEFT(C33,3)="09S",LEFT(C33,14),C33) -> NXH0HAL001832D5D789501 | E33: =IF(LEFT(C33,3)="09S",MID(C33,15,5),"") | F33: 415295 | G33: Acer Chromebook 11 C731 (N16Q13) preto | H33: =IFERROR(INDEX(Sistema!$F$2:$F$421,MATCH(D33,Sistema!$G$2:$G$421,0)),"Não encontrado") -> Carrinho 02 ( AMARELO) | I33: =IFERROR(INDEX(Sistema!$C$2:$C$421,MATCH(D33,Sistema!$G$2:$G$421,0)),"") -> Acer Chromebook 11 N7 (C731, C731T) | J33: =IF(LEFT(C33,3)="09S",IFERROR(MID(INDEX(Sistema!$D$2:$D$421,MATCH(D33,Sistema!$G$2:$G$421,0)),15,5),""),"") | K33: =IF(H33="Não encontrado","Não encontrado",IF(H33<>A33,"Local diferente",IF(AND(E33<>"",J33<>"",UPPER(E33)<>UPPER(J33)),"Letra final diferente","Confere"))) -> Confere | M33: as teclas seta cima, seta direita e seta baixa faltando
A34: Carrinho 02 ( AMARELO) | B34: 3 | C34: NXH0HAL001832D66CA9501 | D34: =IF(LEFT(C34,3)="09S",LEFT(C34,14),C34) -> NXH0HAL001832D66CA9501 | E34: =IF(LEFT(C34,3)="09S",MID(C34,15,5),"") | F34: 413923 | G34: Acer Chromebook 11 C731 (N16Q13) preto | H34: =IFERROR(INDEX(Sistema!$F$2:$F$421,MATCH(D34,Sistema!$G$2:$G$421,0)),"Não encontrado") -> Carrinho 02 ( AMARELO) | I34: =IFERROR(INDEX(Sistema!$C$2:$C$421,MATCH(D34,Sistema!$G$2:$G$421,0)),"") -> Acer Chromebook 11 N7 (C731, C731T) | J34: =IF(LEFT(C34,3)="09S",IFERROR(MID(INDEX(Sistema!$D$2:$D$421,MATCH(D34,Sistema!$G$2:$G$421,0)),15,5),""),"") | K34: =IF(H34="Não encontrado","Não encontrado",IF(H34<>A34,"Local diferente",IF(AND(E34<>"",J34<>"",UPPER(E34)<>UPPER(J34)),"Letra final diferente","Confere"))) -> Confere
A35: Carrinho 02 ( AMARELO) | B35: 4 | C35: NXH0HAL001832D6B599501 | D35: =IF(LEFT(C35,3)="09S",LEFT(C35,14),C35) -> NXH0HAL001832D6B599501 | E35: =IF(LEFT(C35,3)="09S",MID(C35,15,5),"") | F35: 413944 | G35: Acer Chromebook 11 C731 (N16Q13) preto | H35: =IFERROR(INDEX(Sistema!$F$2:$F$421,MATCH(D35,Sistema!$G$2:$G$421,0)),"Não encontrado") -> Carrinho 02 ( AMARELO) | I35: =IFERROR(INDEX(Sistema!$C$2:$C$421,MATCH(D35,Sistema!$G$2:$G$421,0)),"") -> Acer Chromebook 11 N7 (C731, C731T) | J35: =IF(LEFT(C35,3)="09S",IFERROR(MID(INDEX(Sistema!$D$2:$D$421,MATCH(D35,Sistema!$G$2:$G$421,0)),15,5),""),"") | K35: =IF(H35="Não encontrado","Não encontrado",IF(H35<>A35,"Local diferente",IF(AND(E35<>"",J35<>"",UPPER(E35)<>UPPER(J35)),"Letra final diferente","Confere"))) -> Confere
